SQL failed ('main', 1375, 'accept'): 
UPDATE tasks 
SET do = 'use.apply_aspect fucks up q()

Traceback (most recent call last):
  File "E:\Dropbox\code\watnu\master\src\main.py", line 76, in <module>
    q("Python:", sys.version)
  File "E:\Dropbox\code\watnu\master\src\q.py", line 338, in __call__
    info = self.inspect.getframeinfo(self.sys._getframe(1), context=9)
           ^^^^^^^^^^^^^^^^^^^^^^^^^^^^^^^^^^^^^^^^^^^^^^^^^^^^^^^^^^^
  File "C:\Users\micro\AppData\Local\Programs\Python\Python311\Lib\inspect.py", line 1700, in getframeinfo
    lines, lnum = findsource(frame)
                  ^^^^^^^^^^^^^^^^^
  File "C:\Users\micro\AppData\Local\Programs\Python\Python311\Lib\inspect.py", line 1075, in findsource
    module = getmodule(object, file)
             ^^^^^^^^^^^^^^^^^^^^^^^
  File "C:\Users\micro\AppData\Local\Programs\Python\Python311\Lib\inspect.py", line 998, in getmodule
    f = getabsfile(module)
        ^^^^^^^^^^^^^^^^^^
  File "C:\Users\micro\AppData\Local\Programs\Python\Python311\Lib\inspect.py", line 967, in getabsfile
    _filename = getsourcefile(object) or getfile(object)
                ^^^^^^^^^^^^^^^^^^^^^
  File "C:\Users\micro\AppData\Local\Programs\Python\Python311\Lib\inspect.py", line 943, in getsourcefile
    if any(filename.endswith(s) for s in all_bytecode_suffixes):
       ^^^^^^^^^^^^^^^^^^^^^^^^^^^^^^^^^^^^^^^^^^^^^^^^^^^^^^^^
  File "C:\Users\micro\AppData\Local\Programs\Python\Python311\Lib\inspect.py", line 943, in <genexpr>
    if any(filename.endswith(s) for s in all_bytecode_suffixes):
           ^^^^^^^^^^^^^^^^^
AttributeError: 'function' object has no attribute 'endswith'
',
    priority = 0.0,
    level_id = 0,
    primary_activity_id = NULL,
    secondary_activity_id = NULL,
    space_id = 0,
    ilk = 1
WHERE id=287
